Workbook

Sheet Full Chart
A1: Primary Serial | B1: Hashrate | C1: Sticker | D1: Model Serial | E1: Model | F1: Side Serial | G1: Year Serial | H1: YearOM | I1: Rated J/TH | J1: Calc Watts | K1: Env. | L1: Hashboard | M1: Hashboard Serial | N1: ASIC Chip | O1: ASICs/HB | P1: # HB | Q1: Total ASIC | R1: Power Supply | S1: PSU HW Code | T1: Control Board Options | U1: CV Prevalence | V1: HB Material | W1: Temp Sens/HB | X1: PIC/MOS | Y1: Heatsink Type | Z1: Fan Size | AA1: Fan RPM | AB1: Chassis Size | AC1: PSU Size | AD1: Power Connector | AE1: AC Voltage Range | AF1: LPM | AG1: LPM Update Req. | AH1: HEM | AI1: Stock FW - FMT | AJ1: Vnish FW - FMT | AK1: Reference Model | AL1: Favorites
A2: 67A | B2: 110 | C2: S19 Pro_110T | D2: =MID(A2,1,2) -> 67 | E2: S19 Pro | F2: 67U | G2: J | H2: 2020 | I2: 29.5 | J2: =B2*I2 -> 3245 | K2: Air | L2: NBS1901 | M2: YI3 | N2: BM1398 | O2: 114 | P2: 3 | Q2: =O2*P2 -> 342 | R2: APW121215ABC | S2: 0x71, 0x72, 0x73 | T2: Xilinx | U2: 0 | V2: FR4 | W2: 4 | X2: Yes | Y2: Solid Plate | Z2: 120mm | AA2: 6000 | AB2: S19 Short-30mm | AC2: Normal Size | AD2: 2x C13 | AE2: 200-240V | AF2: Yes | AG2: December 2022 | AH2: No | AI2: =_xlfn.TEXTBEFORE(C2,"_") & " (" & _xlfn.TEXTAFTER(C2,"_") & ")" -> S19 Pro (110T) | AJ2: =_xlfn.TEXTBEFORE(C2,"_") & " (Vnish)" -> S19 Pro (Vnish) | AK2: 1 | AL2: 1
A3: 67B | B3: 105 | C3: S19 Pro_105T | D3: =MID(A3,1,2) -> 67 | E3: S19 Pro | F3: 67U | G3: J | H3: 2020 | I3: 29.5 | J3: =B3*I3 -> 3097.5 | K3: Air | L3: NBS1901 | M3: YI3 | N3: BM1398 | O3: 114 | P3: 3 | Q3: =O3*P3 -> 342 | R3: APW121215ABC | S3: 0x71, 0x72, 0x73 | T3: Xilinx | U3: 0 | V3: FR4 | W3: 4 | X3: Yes | Y3: Solid Plate | Z3: 120mm | AA3: 6000 | AB3: S19 Short-30mm | AC3: Normal Size | AD3: 2x C13 | AE3: 200-240V | AF3: Yes | AG3: December 2022 | AH3: No | AI3: =_xlfn.TEXTBEFORE(C3,"_") & " (" & _xlfn.TEXTAFTER(C3,"_") & ")" -> S19 Pro (105T) | AJ3: =_xlfn.TEXTBEFORE(C3,"_") & " (Vnish)" -> S19 Pro (Vnish) | AK3: 0 | AL3: 0
A4: 68A | B4: 95 | C4: S19_95T | D4: =MID(A4,1,2) -> 68 | E4: S19 | F4: 68U | G4: J | H4: 2020 | I4: 34 | J4: =B4*I4 -> 3230 | K4: Air | L4: NBS1902 | N4: BM1398 | O4: 76 | P4: 3 | Q4: =O4*P4 -> 228 | R4: APW121215ABC | S4: 0x71, 0x72, 0x73 | T4: Xilinx | U4: 0 | V4: FR4 | W4: 4 | X4: Yes | Y4: Solid Plate | Z4: 120mm | AA4: 6000 | AB4: S19 Normal-60mm | AC4: Normal Size | AD4: 2x C13 | AE4: 200-240V | AF4: Yes | AG4: December 2022 | AH4: No | AI4: =_xlfn.TEXTBEFORE(C4,"_") & " (" & _xlfn.TEXTAFTER(C4,"_") & ")" -> S19 (95T) | AJ4: =_xlfn.TEXTBEFORE(C4,"_") & " (Vnish)" -> S19 (Vnish) | AK4: 1 | AL4: 1
A5: 68B | B5: 90 | C5: S19_90T | D5: =MID(A5,1,2) -> 68 | E5: S19 | F5: 68U | G5: J | H5: 2020 | I5: 36 | J5: =B5*I5 -> 3240 | K5: Air | L5: NBS1902 | N5: BM1398 | O5: 76 | P5: 3 | Q5: =O5*P5 -> 228 | R5: APW121215ABC | S5: 0x71, 0x72, 0x73 | T5: Xilinx | U5: 0 | V5: FR4 | W5: 4 | X5: Yes | Y5: Solid Plate | Z5: 120mm | AA5: 6000 | AB5: S19 Normal-60mm | AC5: Normal Size | AD5: 2x C13 | AE5: 200-240V | AF5: Yes | AG5: December 2022 | AH5: No | AI5: =_xlfn.TEXTBEFORE(C5,"_") & " (" & _xlfn.TEXTAFTER(C5,"_") & ")" -> S19 (90T) | AJ5: =_xlfn.TEXTBEFORE(C5,"_") & " (Vnish)" -> S19 (Vnish) | AK5: 0 | AL5: 0
A6: A0A | B6: 88 | C6: T19_88T | D6: =MID(A6,1,2) -> A0 | E6: T19 | F6: A0U | G6: J | H6: 2020 | I6: 37.5 | J6: =B6*I6 -> 3300 | K6: Air | L6: NBS1903 | N6: BM1398 | O6: 76 | P6: 3 | Q6: =O6*P6 -> 228 | R6: APW121215ABC | S6: 0x71, 0x72, 0x73 | T6: Xilinx | U6: 0 | V6: FR4 | W6: 4 | X6: Yes | Y6: Solid Plate | Z6: 120mm | AA6: 6000 | AB6: S19 Normal-60mm | AC6: Normal Size | AD6: 2x C13 | AE6: 200-240V | AF6: Yes | AG6: December 2022 | AH6: No | AI6: =_xlfn.TEXTBEFORE(C6,"_") & " (" & _xlfn.TEXTAFTER(C6,"_") & ")" -> T19 (88T) | AJ6: =_xlfn.TEXTBEFORE(C6,"_") & " (Vnish)" -> T19 (Vnish) | AK6: 0 | AL6: 0
A7: A0B | B7: 84 | C7: T19_84T | D7: =MID(A7,1,2) -> A0 | E7: T19 | F7: A0U | G7: J | H7: 2020 | I7: 37.5 | J7: =B7*I7 -> 3150 | K7: Air | L7: NBS1903 | N7: BM1398 | O7: 76 | P7: 3 | Q7: =O7*P7 -> 228 | R7: APW121215ABC | S7: 0x71, 0x72, 0x73 | T7: Xilinx | U7: 0 | V7: FR4 | W7: 4 | X7: Yes | Y7: Solid Plate | Z7: 120mm | AA7: 6000 | AB7: S19 Normal-60mm | AC7: Normal Size | AD7: 2x C13 | AE7: 200-240V | AF7: Yes | AG7: December 2022 | AH7: No | AI7: =_xlfn.TEXTBEFORE(C7,"_") & " (" & _xlfn.TEXTAFTER(C7,"_") & ")" -> T19 (84T) | AJ7: =_xlfn.TEXTBEFORE(C7,"_") & " (Vnish)" -> T19 (Vnish) | AK7: 1 | AL7: 0
A8: ADA | B8: 120 | C8: S19j Pro+_120T | D8: =MID(A8,1,2) -> AD | E8: S19j Pro+ | F8: ADU | G8: C | H8: 2023 | I8: 27.5 | J8: =B8*I8 -> 3300 | K8: Air | L8: BHB42612 | M8: YR5 | N8: BM1362 | O8: 120 | P8: 3 | Q8: =O8*P8 -> 360 | R8: APW121215DEF | S8: 0x74, 0x75, 0x76 | T8: Xilinx, AML | U8: 0.001 | V8: FR4 | W8: 2 | X8: No | Y8: Ind. Soldered | Z8: 120mm | AA8: 6000 | AB8: S19 Normal-60mm | AC8: Normal Size | AD8: 2x C13 | AE8: 200-240V | AF8: Yes | AG8: Initial | AH8: No | AI8: =_xlfn.TEXTBEFORE(C8,"_") & " (" & _xlfn.TEXTAFTER(C8,"_") & ")" -> S19j Pro+ (120T) | AJ8: =_xlfn.TEXTBEFORE(C8,"_") & " (Vnish)" -> S19j Pro+ (Vnish) | AK8: 1 | AL8: 1
A9: ADB | B9: 117 | C9: S19j Pro+_117T | D9: =MID(A9,1,2) -> AD | E9: S19j Pro+ | F9: ADU | G9: C | H9: 2023 | I9: 27.5 | J9: =B9*I9 -> 3217.5 | K9: Air | L9: BHB42612 | M9: YR5 | N9: BM1362 | O9: 120 | P9: 3 | Q9: =O9*P9 -> 360 | R9: APW121215DEF | S9: 0x74, 0x75, 0x76 | T9: Xilinx, AML | U9: 0.001 | V9: FR4 | W9: 2 | X9: No | Y9: Ind. Soldered | Z9: 120mm | AA9: 6000 | AB9: S19 Normal-60mm | AC9: Normal Size | AD9: 2x C13 | AE9: 200-240V | AF9: Yes | AG9: Initial | AH9: No | AI9: =_xlfn.TEXTBEFORE(C9,"_") & " (" & _xlfn.TEXTAFTER(C9,"_") & ")" -> S19j Pro+ (117T) | AJ9: =_xlfn.TEXTBEFORE(C9,"_") & " (Vnish)" -> S19j Pro+ (Vnish) | AK9: 0 | AL9: 1
A10: ADC | B10: 113 | C10: S19j Pro+_113T | D10: =MID(A10,1,2) -> AD | E10: S19j Pro+ | F10: ADU | G10: C | H10: 2023 | I10: 27.5 | J10: =B10*I10 -> 3107.5 | K10: Air | L10: BHB42612 | M10: YR5 | N10: BM1362 | O10: 120 | P10: 3 | Q10: =O10*P10 -> 360 | R10: APW121215DEF | S10: 0x74, 0x75, 0x76 | T10: Xilinx, AML | U10: 0.001 | V10: FR4 | W10: 2 | X10: No | Y10: Ind. Soldered | Z10: 120mm | AA10: 6000 | AB10: S19 Normal-60mm | AC10: Normal Size | AD10: 2x C13 | AE10: 200-240V | AF10: Yes | AG10: Initial | AH10: No | AI10: =_xlfn.TEXTBEFORE(C10,"_") & " (" & _xlfn.TEXTAFTER(C10,"_") & ")" -> S19j Pro+ (113T) | AJ10: =_xlfn.TEXTBEFORE(C10,"_") & " (Vnish)" -> S19j Pro+ (Vnish) | AK10: 0 | AL10: 0
A11: AEA | B11: 120 | C11: S19k Pro_120T | D11: =MID(A11,1,2) -> AE | E11: S19k Pro | F11: AEU | G11: C | H11: 2023 | I11: 23 | J11: =B11*I11 -> 2760 | K11: Air | L11: BHB56902 | N11: BM1366 | O11: 77 | P11: 3 | Q11: =O11*P11 -> 231 | R11: APW121215DEF | S11: 0x74, 0x75, 0x76 | T11: Xilinx, AML, CV | U11: 0.5 | V11: FR4 | W11: 2 | X11: No | Y11: Ind. Soldered | Z11: 120mm | AA11: 6000/7000 | AB11: S19 Normal-60mm | AC11: Normal Size | AD11: 2x C13 | AE11: 200-240V | AF11: No | AG11: N/A | AH11: Yes | AI11: =_xlfn.TEXTBEFORE(C11,"_") & " (" & _xlfn.TEXTAFTER(C11,"_") & ")" -> S19k Pro (120T) | AJ11: =_xlfn.TEXTBEFORE(C11,"_") & " (Vnish)" -> S19k Pro (Vnish) | AK11: 1 | AL11: 0
A12: AEB | B12: 115 | C12: S19k Pro_115T | D12: =MID(A12,1,2) -> AE | E12: S19k Pro | F12: AEU | G12: C | H12: 2023 | I12: 23 | J12: =B12*I12 -> 2645 | K12: Air | L12: BHB56902 | N12: BM1366 | O12: 77 | P12: 3 | Q12: =O12*P12 -> 231 | R12: APW121215DEF | S12: 0x74, 0x75, 0x76 | T12: Xilinx, AML, CV | U12: 0.5 | V12: FR4 | W12: 2 | X12: No | Y12: Ind. Soldered | Z12: 120mm | AA12: 6000/7000 | AB12: S19 Normal-60mm | AC12: Normal Size | AD12: 2x C13 | AE12: 200-240V | AF12: No | AG12: N/A | AH12: Yes | AI12: =_xlfn.TEXTBEFORE(C12,"_") & " (" & _xlfn.TEXTAFTER(C12,"_") & ")" -> S19k Pro (115T) | AJ12: =_xlfn.TEXTBEFORE(C12,"_") & " (Vnish)" -> S19k Pro (Vnish) | AK12: 0 | AL12: 0
A13: AEC | B13: 110 | C13: S19k Pro_110T | D13: =MID(A13,1,2) -> AE | E13: S19k Pro | F13: AEU | G13: C | H13: 2023 | I13: 23 | J13: =B13*I13 -> 2530 | K13: Air | L13: BHB56902 | N13: BM1366 | O13: 77 | P13: 3 | Q13: =O13*P13 -> 231 | R13: APW121215DEF | S13: 0x74, 0x75, 0x76 | T13: Xilinx, AML, CV | U13: 0.5 | V13: FR4 | W13: 2 | X13: No | Y13: Ind. Soldered | Z13: 120mm | AA13: 6000/7000 | AB13: S19 Normal-60mm | AC13: Normal Size | AD13: 2x C13 | AE13: 200-240V | AF13: No | AG13: N/A | AH13: Yes | AI13: =_xlfn.TEXTBEFORE(C13,"_") & " (" & _xlfn.TEXTAFTER(C13,"_") & ")" -> S19k Pro (110T) | AJ13: =_xlfn.TEXTBEFORE(C13,"_") & " (Vnish)" -> S19k Pro (Vnish) | AK13: 0 | AL13: 0
A14: AHA | B14: 335 | C14: S21 Hyd._335T | D14: AH | E14: S21 Hyd. | F14: AHU | G14: D | H14: 2024 | I14: 16 | J14: =B14*I14 -> 5360 | K14: Hydro | L14: HHB68501 | N14: BM1368 | O14: 216 | P14: 3 | Q14: =O14*P14 -> 648 | R14: APW111721 (Hyd) | S14: Unknown | T14: Xilinx (Hydro) | U14: 0 | V14: FR4 | W14: 2 | X14: No | Y14: Liquid-to-Chip | Z14: N/A | AA14: N/A | AB14: Hydro Size | AC14: Hydro Size | AD14: LP-20-4 | AE14: 380-415V | AF14: No | AG14: N/A | AH14: Unknown | AI14: =_xlfn.TEXTBEFORE(C14,"_") & " (" & _xlfn.TEXTAFTER(C14,"_") & ")" -> S21 Hyd. (335T) | AJ14: =_xlfn.TEXTBEFORE(C14,"_") & " (Vnish)" -> S21 Hyd. (Vnish) | AK14: 1 | AL14: 0
A15: AHB | B15: 319 | C15: S21 Hyd._319T | D15: AH | E15: S21 Hyd. | F15: AHU | G15: D | H15: 2024 | I15: 16 | J15: =B15*I15 -> 5104 | K15: Hydro | L15: HHB68501 | N15: BM1368 | O15: 216 | P15: 3 | Q15: =O15*P15 -> 648 | R15: APW111721 (Hyd) | S15: Unknown | T15: Xilinx (Hydro) | U15: 0 | V15: FR4 | W15: 2 | X15: No | Y15: Liquid-to-Chip | Z15: N/A | AA15: N/A | AB15: Hydro Size | AC15: Hydro Size | AD15: LP-20-4 | AE15: 380-415V | AF15: No | AG15: N/A | AH15: Unknown | AI15: =_xlfn.TEXTBEFORE(C15,"_") & " (" & _xlfn.TEXTAFTER(C15,"_") & ")" -> S21 Hyd. (319T) | AJ15: =_xlfn.TEXTBEFORE(C15,"_") & " (Vnish)" -> S21 Hyd. (Vnish) | AK15: 0 | AL15: 0
A16: ANA | B16: 151 | C16: S19j XP_151T | D16: AN | E16: S19j XP | F16: ANU | G16: C | H16: 2023 | I16: 21.5 | J16: =B16*I16 -> 3246.5 | K16: Air | L16: Unknown | N16: BM1366 | O16: 110 | P16: 3 | Q16: =O16*P16 -> 330 | R16: APW171215A | S16: 0xc1 | T16: Xilinx, AML, CV | U16: 0.5 | V16: Aluminum | W16: 2 | X16: No | Y16: Solid Plate | Z16: 120mm | AA16: 6000 | AB16: S19 Normal-60mm | AC16: Normal Size | AD16: P13 (4 Pin) | AE16: 220-277V | AF16: Unknown | AG16: Unknown | AH16: Unknown | AI16: =_xlfn.TEXTBEFORE(C16,"_") & " (" & _xlfn.TEXTAFTER(C16,"_") & ")" -> S19j XP (151T) | AJ16: =_xlfn.TEXTBEFORE(C16,"_") & " (Vnish)" -> S19j XP (Vnish) | AK16: 1 | AL16: 0
A17: ATA | B17: 200 | C17: S21_200T | D17: =MID(A17,1,2) -> AT | E17: S21 | F17: ATU | G17: C/D | H17: 2023/2024 | I17: 17.5 | J17: =B17*I17 -> 3500 | K17: Air | L17: BHB68603 | M17: YRH | N17: BM1368 | O17: 108 | P17: 3 | Q17: =O17*P17 -> 324 | R17: APW171215A | S17: 0xc1 | T17: AML | U17: 0 | V17: Aluminum | W17: 2 | X17: No | Y17: Solid Plate | Z17: 120mm | AA17: 7000 | AB17: S19 Normal-60mm | AC17: Normal Size | AD17: P13 (4 Pin) | AE17: 220-277V | AF17: Yes | AG17: Initial | AH17: No | AI17: =_xlfn.TEXTBEFORE(C17,"_") & " (" & _xlfn.TEXTAFTER(C17,"_") & ")" -> S21 (200T) | AJ17: =_xlfn.TEXTBEFORE(C17,"_") & " (Vnish)" -> S21 (Vnish) | AK17: 1 | AL17: 1
A18: ATB | B18: 188 | C18: S21_188T | D18: =MID(A18,1,2) -> AT | E18: S21 | F18: ATU | G18: C/D | H18: 2023/2024 | I18: 17.5 | J18: =B18*I18 -> 3290 | K18: Air | L18: BHB68603 | M18: YRH | N18: BM1368 | O18: 108 | P18: 3 | Q18: =O18*P18 -> 324 | R18: APW171215A | S18: 0xc1 | T18: AML | U18: 0 | V18: Aluminum | W18: 2 | X18: No | Y18: Solid Plate | Z18: 120mm | AA18: 7000 | AB18: S19 Normal-60mm | AC18: Normal Size | AD18: P13 (4 Pin) | AE18: 220-277V | AF18: Yes | AG18: Initial | AH18: No | AI18: =_xlfn.TEXTBEFORE(C18,"_") & " (" & _xlfn.TEXTAFTER(C18,"_") & ")" -> S21 (188T) | AJ18: =_xlfn.TEXTBEFORE(C18,"_") & " (Vnish)" -> S21 (Vnish) | AK18: 0 | AL18: 1
A19: ATD | B19: 195 | C19: S21_195T | D19: =MID(A19,1,2) -> AT | E19: S21 | F19: ATU | G19: C/D | H19: 2023/2024 | I19: 17.5 | J19: =B19*I19 -> 3412.5 | K19: Air | L19: BHB68603 | M19: YRH | N19: BM1368 | O19: 108 | P19: 3 | Q19: =O19*P19 -> 324 | R19: APW171215A | S19: 0xc1 | T19: AML | U19: 0 | V19: Aluminum | W19: 2 | X19: No | Y19: Solid Plate | Z19: 120mm | AA19: 7000 | AB19: S19 Normal-60mm | AC19: Normal Size | AD19: P13 (4 Pin) | AE19: 220-277V | AF19: Yes | AG19: Initial | AH19: No | AI19: =_xlfn.TEXTBEFORE(C19,"_") & " (" & _xlfn.TEXTAFTER(C19,"_") & ")" -> S21 (195T) | AJ19: =_xlfn.TEXTBEFORE(C19,"_") & " (Vnish)" -> S21 (Vnish) | AK19: 0 | AL19: 1
A20: AWA | B20: 141 | C20: S19 XP_141T | D20: =MID(A20,1,2) -> AW | E20: S19 XP | F20: AWU | G20: C | H20: 2023 | I20: 21.5 | J20: =B20*I20 -> 3031.5 | K20: Air | L20: BHB56806 | M20: YRJ | N20: BM1366 | O20: 110 | P20: 3 | Q20: =O20*P20 -> 330 | R20: APW121215DEF | S20: 0x74, 0x75, 0x76 | T20: Xilinx, AML, CV | U20: 0.5 | V20: Aluminum | W20: 2 | X20: No | Y20: Solid Plate | Z20: 120mm | AA20: 6000 | AB20: S19 Normal-60mm | AC20: Normal Size | AD20: 2x C13 | AE20: 200-240V | AF20: Yes | AG20: July 2023 | AH20: No | AI20: =_xlfn.TEXTBEFORE(C20,"_") & " (" & _xlfn.TEXTAFTER(C20,"_") & ")" -> S19 XP (141T) | AJ20: =_xlfn.TEXTBEFORE(C20,"_") & " (Vnish)" -> S19 XP (Vnish) | AK20: 0 | AL20: 1
A21: AWB | B21: 134 | C21: S19 XP_134T | D21: =MID(A21,1,2) -> AW | E21: S19 XP | F21: AWU | G21: C | H21: 2023 | I21: 21.5 | J21: =B21*I21 -> 2881 | K21: Air | L21: BHB56806 | M21: YRJ | N21: BM1366 | O21: 110 | P21: 3 | Q21: =O21*P21 -> 330 | R21: APW121215DEF | S21: 0x74, 0x75, 0x76 | T21: Xilinx, AML, CV | U21: 0.5 | V21: Aluminum | W21: 2 | X21: No | Y21: Solid Plate | Z21: 120mm | AA21: 6000 | AB21: S19 Normal-60mm | AC21: Normal Size | AD21: 2x C13 | AE21: 200-240V | AF21: Yes | AG21: July 2023 | AH21: No | AI21: =_xlfn.TEXTBEFORE(C21,"_") & " (" & _xlfn.TEXTAFTER(C21,"_") & ")" -> S19 XP (134T) | AJ21: =_xlfn.TEXTBEFORE(C21,"_") & " (Vnish)" -> S19 XP (Vnish) | AK21: 0 | AL21: 1
A22: AWC | B22: 127 | C22: S19 XP_127T | D22: =MID(A22,1,2) -> AW | E22: S19 XP | F22: AWU | G22: C | H22: 2023 | I22: 21.5 | J22: =B22*I22 -> 2730.5 | K22: Air | L22: BHB56806 | M22: YRJ | N22: BM1366 | O22: 110 | P22: 3 | Q22: =O22*P22 -> 330 | R22: APW121215DEF | S22: 0x74, 0x75, 0x76 | T22: Xilinx, AML, CV | U22: 0.5 | V22: Aluminum | W22: 2 | X22: No | Y22: Solid Plate | Z22: 120mm | AA22: 6000 | AB22: S19 Normal-60mm | AC22: Normal Size | AD22: 2x C13 | AE22: 200-240V | AF22: Yes | AG22: July 2023 | AH22: No | AI22: =_xlfn.TEXTBEFORE(C22,"_") & " (" & _xlfn.TEXTAFTER(C22,"_") & ")" -> S19 XP (127T) | AJ22: =_xlfn.TEXTBEFORE(C22,"_") & " (Vnish)" -> S19 XP (Vnish) | AK22: 0 | AL22: 1
A23: B0A | B23: 120 | C23: S19k Pro_120T | D23: =MID(A23,1,2) -> B0 | E23: S19k Pro | F23: B0U | G23: D | H23: 2024 | I23: 23 | J23: =B23*I23 -> 2760 | K23: Air | L23: BHB56903 | N23: BM1366 | O23: 77 | P23: 3 | Q23: =O23*P23 -> 231 | R23: APW121215DEF | S23: 0x74, 0x75, 0x76 | T23: Xilinx, AML, CV | U23: 0.95 | V23: Aluminum | W23: 2 | X23: No | Y23: Ind. Soldered | Z23: 120mm | AA23: 6000/7000 | AB23: S19 Normal-60mm | AC23: Normal Size | AD23: 2x C13 | AE23: 200-240V | AF23: No | AG23: N/A | AH23: Yes | AI23: =_xlfn.TEXTBEFORE(C23,"_") & " (" & _xlfn.TEXTAFTER(C23,"_") & ")" -> S19k Pro (120T) | AJ23: =_xlfn.TEXTBEFORE(C23,"_") & " (Vnish)" -> S19k Pro (Vnish) | AK23: 0 | AL23: 0
A24: B0B | B24: 115 | C24: S19k Pro_115T | D24: =MID(A24,1,2) -> B0 | E24: S19k Pro | F24: B0U | G24: D | H24: 2024 | I24: 23 | J24: =B24*I24 -> 2645 | K24: Air | L24: BHB56903 | N24: BM1366 | O24: 77 | P24: 3 | Q24: =O24*P24 -> 231 | R24: APW121215DEF | S24: 0x74, 0x75, 0x76 | T24: Xilinx, AML, CV | U24: 0.95 | V24: Aluminum | W24: 2 | X24: No | Y24: Ind. Soldered | Z24: 120mm | AA24: 6000/7000 | AB24: S19 Normal-60mm | AC24: Normal Size | AD24: 2x C13 | AE24: 200-240V | AF24: No | AG24: N/A | AH24: Yes | AI24: =_xlfn.TEXTBEFORE(C24,"_") & " (" & _xlfn.TEXTAFTER(C24,"_") & ")" -> S19k Pro (115T) | AJ24: =_xlfn.TEXTBEFORE(C24,"_") & " (Vnish)" -> S19k Pro (Vnish) | AK24: 0 | AL24: 0
A25: B0C | B25: 110 | C25: S19k Pro_110T | D25: =MID(A25,1,2) -> B0 | E25: S19k Pro | F25: B0U | G25: D | H25: 2024 | I25: 23 | J25: =B25*I25 -> 2530 | K25: Air | L25: BHB56903 | N25: BM1366 | O25: 77 | P25: 3 | Q25: =O25*P25 -> 231 | R25: APW121215DEF | S25: 0x74, 0x75, 0x76 | T25: Xilinx, AML, CV | U25: 0.95 | V25: Aluminum | W25: 2 | X25: No | Y25: Ind. Soldered | Z25: 120mm | AA25: 6000/7000 | AB25: S19 Normal-60mm | AC25: Normal Size | AD25: 2x C13 | AE25: 200-240V | AF25: No | AG25: N/A | AH25: Yes | AI25: =_xlfn.TEXTBEFORE(C25,"_") & " (" & _xlfn.TEXTAFTER(C25,"_") & ")" -> S19k Pro (110T) | AJ25: =_xlfn.TEXTBEFORE(C25,"_") & " (Vnish)" -> S19k Pro (Vnish) | AK25: 0 | AL25: 0
A26: B9D | B26: 88.5 | C26: S19i_88.5T | D26: =MID(A26,1,2) -> B9 | E26: S19i | F26: B9U | G26: A | H26: 2021 | I26: 34.5 | J26: =B26*I26 -> 3053.25 | K26: Air | L26: NBS2003 | N26: BM1398 | O26: 80 | P26: 3 | Q26: =O26*P26 -> 240 | R26: APW121215ABC | S26: 0x71, 0x72, 0x73 | T26: Xilinx | U26: 0 | V26: FR4 | W26: Unknown | X26: Yes | Y26: Solid Plate | Z26: 120mm | AA26: 6000 | AB26: S19 Size | AC26: Normal Size | AD26: 2x C13 | AE26: 200-240V | AF26: Unknown | AG26: Unknown | AH26: Unknown | AI26: =_xlfn.TEXTBEFORE(C26,"_") & " (" & _xlfn.TEXTAFTER(C26,"_") & ")" -> S19i (88.5T) | AJ26: =_xlfn.TEXTBEFORE(C26,"_") & " (Vnish)" -> S19i (Vnish) | AK26: 0 | AL26: 0
A27: B9E | B27: 92.5 | C27: S19i_92.5T | D27: =MID(A27,1,2) -> B9 | E27: S19i | F27: B9U | G27: A | H27: 2021 | I27: 34.5 | J27: =B27*I27 -> 3191.25 | K27: Air | L27: NBS2003 | N27: BM1398 | O27: 80 | P27: 3 | Q27: =O27*P27 -> 240 | R27: APW121215ABC | S27: 0x71, 0x72, 0x73 | T27: Xilinx | U27: 0 | V27: FR4 | W27: Unknown | X27: Yes | Y27: Solid Plate | Z27: 120mm | AA27: 6000 | AB27: S19 Size | AC27: Normal Size | AD27: 2x C13 | AE27: 200-240V | AF27: Unknown | AG27: Unknown | AH27: Unknown | AI27: =_xlfn.TEXTBEFORE(C27,"_") & " (" & _xlfn.TEXTAFTER(C27,"_") & ")" -> S19i (92.5T) | AJ27: =_xlfn.TEXTBEFORE(C27,"_") & " (Vnish)" -> S19i (Vnish) | AK27: 1 | AL27: 0
A28: C2A | B28: 90 | C28: S19_90T | D28: =MID(A28,1,2) -> C2 | E28: S19 | F28: C2U | G28: A/B | H28: 2021/2022 | I28: 34.5 | J28: =B28*I28 -> 3105 | K28: Air | L28: BHB42801 | N28: BM1362 | O28: 88 | P28: 3 | Q28: =O28*P28 -> 264 | R28: APW121417A | S28: Unknown | T28: Xilinx, AML | U28: 0 | V28: Aluminum | W28: 4 | X28: Yes | Y28: Solid Plate | Z28: 120mm | AA28: 6000 | AB28: S19 Long-90mm | AC28: Normal Size | AD28: 2x C13 | AE28: 200-240V | AF28: Yes | AG28: December 2022 | AH28: No | AI28: =_xlfn.TEXTBEFORE(C28,"_") & " (" & _xlfn.TEXTAFTER(C28,"_") & ")" -> S19 (90T) | AJ28: =_xlfn.TEXTBEFORE(C28,"_") & " (Vnish)" -> S19 (Vnish) | AK28: 1 | AL28: 0
A29: C2B | B29: 86 | C29: S19_86T | D29: =MID(A29,1,2) -> C2 | E29: S19 | F29: C2U | G29: A/B | H29: 2021/2022 | I29: 34.5 | J29: =B29*I29 -> 2967 | K29: Air | L29: BHB42801 | N29: BM1362 | O29: 88 | P29: 3 | Q29: =O29*P29 -> 264 | R29: APW121417A | S29: Unknown | T29: Xilinx, AML | U29: 0 | V29: Aluminum | W29: 4 | X29: Yes | Y29: Solid Plate | Z29: 120mm | AA29: 6000 | AB29: S19 Long-90mm | AC29: Normal Size | AD29: 2x C13 | AE29: 200-240V | AF29: Yes | AG29: December 2022 | AH29: No | AI29: =_xlfn.TEXTBEFORE(C29,"_") & " (" & _xlfn.TEXTAFTER(C29,"_") & ")" -> S19 (86T) | AJ29: =_xlfn.TEXTBEFORE(C29,"_") & " (Vnish)" -> S19 (Vnish) | AK29: 0 | AL29: 0
A30: C2C | B30: 82 | C30: S19_82T | D30: =MID(A30,1,2) -> C2 | E30: S19 | F30: C2U | G30: A/B | H30: 2021/2022 | I30: 34.5 | J30: =B30*I30 -> 2829 | K30: Air | L30: BHB42801 | N30: BM1362 | O30: 88 | P30: 3 | Q30: =O30*P30 -> 264 | R30: APW121417A | S30: Unknown | T30: Xilinx, AML | U30: 0 | V30: Aluminum | W30: 4 | X30: Yes | Y30: Solid Plate | Z30: 120mm | AA30: 6000 | AB30: S19 Long-90mm | AC30: Normal Size | AD30: 2x C13 | AE30: 200-240V | AF30: Yes | AG30: December 2022 | AH30: No | AI30: =_xlfn.TEXTBEFORE(C30,"_") & " (" & _xlfn.TEXTAFTER(C30,"_") & ")" -> S19 (82T) | AJ30: =_xlfn.TEXTBEFORE(C30,"_") & " (Vnish)" -> S19 (Vnish) | AK30: 0 | AL30: 0
A31: D4A | B31: 96 | C31: S19j Pro_96T | D31: =MID(A31,1,2) -> D4 | E31: S19j Pro | F31: D4U | G31: A/B | H31: 2021/2022 | I31: 29.5 | J31: =B31*I31 -> 2832 | K31: Air | L31: BHB42601 | N31: BM1362 | O31: 126 | P31: 3 | Q31: =O31*P31 -> 378 | R31: APW121215ABC | S31: 0x71, 0x72, 0x73 | T31: Xilinx, BB, AML | U31: 0 | V31: FR4 | W31: 4 | X31: Yes | Y31: Solid Plate | Z31: 120mm | AA31: 6000 | AB31: S19 Normal-60mm | AC31: Normal Size | AD31: 2x C13 | AE31: 200-240V | AF31: Yes | AG31: December 2022 | AH31: No | AI31: =_xlfn.TEXTBEFORE(C31,"_") & " (" & _xlfn.TEXTAFTER(C31,"_") & ")" -> S19j Pro (96T) | AJ31: =_xlfn.TEXTBEFORE(C31,"_") & " (Vnish)" -> S19j Pro (Vnish) | AK31: 0 | AL31: 1
A32: D4B | B32: 100 | C32: S19j Pro_100T | D32: =MID(A32,1,2) -> D4 | E32: S19j Pro | F32: D4U | G32: A/B | H32: 2021/2022 | I32: 29.5 | J32: =B32*I32 -> 2950 | K32: Air | L32: BHB42601 | N32: BM1362 | O32: 126 | P32: 3 | Q32: =O32*P32 -> 378 | R32: APW121215ABC | S32: 0x71, 0x72, 0x73 | T32: Xilinx, BB, AML | U32: 0 | V32: FR4 | W32: 4 | X32: Yes | Y32: Solid Plate | Z32: 120mm | AA32: 6000 | AB32: S19 Normal-60mm | AC32: Normal Size | AD32: 2x C13 | AE32: 200-240V | AF32: Yes | AG32: December 2022 | AH32: No | AI32: =_xlfn.TEXTBEFORE(C32,"_") & " (" & _xlfn.TEXTAFTER(C32,"_") & ")" -> S19j Pro (100T) | AJ32: =_xlfn.TEXTBEFORE(C32,"_") & " (Vnish)" -> S19j Pro (Vnish) | AK32: 1 | AL32: 1
A33: D4C | B33: 104 | C33: S19j Pro_104T | D33: =MID(A33,1,2) -> D4 | E33: S19j Pro | F33: D4U | G33: A/B | H33: 2021/2022 | I33: 29.5 | J33: =B33*I33 -> 3068 | K33: Air | L33: BHB42601 | N33: BM1362 | O33: 126 | P33: 3 | Q33: =O33*P33 -> 378 | R33: APW121215ABC | S33: 0x71, 0x72, 0x73 | T33: Xilinx, BB, AML | U33: 0 | V33: FR4 | W33: 4 | X33: Yes | Y33: Solid Plate | Z33: 120mm | AA33: 6000 | AB33: S19 Normal-60mm | AC33: Normal Size | AD33: 2x C13 | AE33: 200-240V | AF33: Yes | AG33: December 2022 | AH33: No | AI33: =_xlfn.TEXTBEFORE(C33,"_") & " (" & _xlfn.TEXTAFTER(C33,"_") & ")" -> S19j Pro (104T) | AJ33: =_xlfn.TEXTBEFORE(C33,"_") & " (Vnish)" -> S19j Pro (Vnish) | AK33: 0 | AL33: 1
A34: D4D | B34: 92 | C34: S19j Pro_92T | D34: =MID(A34,1,2) -> D4 | E34: S19j Pro | F34: D4U | G34: A/B | H34: 2021/2022 | I34: 29.5 | J34: =B34*I34 -> 2714 | K34: Air | L34: BHB42601 | N34: BM1362 | O34: 126 | P34: 3 | Q34: =O34*P34 -> 378 | R34: APW121215ABC | S34: 0x71, 0x72, 0x73 | T34: Xilinx, BB, AML | U34: 0 | V34: FR4 | W34: 4 | X34: Yes | Y34: Solid Plate | Z34: 120mm | AA34: 6000 | AB34: S19 Normal-60mm | AC34: Normal Size | AD34: 2x C13 | AE34: 200-240V | AF34: Yes | AG34: December 2022 | AH34: No | AI34: =_xlfn.TEXTBEFORE(C34,"_") & " (" & _xlfn.TEXTAFTER(C34,"_") & ")" -> S19j Pro (92T) | AJ34: =_xlfn.TEXTBEFORE(C34,"_") & " (Vnish)" -> S19j Pro (Vnish) | AK34: 0 | AL34: 1
A35: D4E | B35: 88 | C35: S19j Pro_88T | D35: =MID(A35,1,2) -> D4 | E35: S19j Pro | F35: D4U | G35: A/B | H35: 2021/2022 | I35: 29.5 | J35: =B35*I35 -> 2596 | K35: Air | L35: BHB42601 | N35: BM1362 | O35: 126 | P35: 3 | Q35: =O35*P35 -> 378 | R35: APW121215ABC | S35: 0x71, 0x72, 0x73 | T35: Xilinx, BB, AML | U35: 0 | V35: FR4 | W35: 4 | X35: Yes | Y35: Solid Plate | Z35: 120mm | AA35: 6000 | AB35: S19 Normal-60mm | AC35: Normal Size | AD35: 2x C13 | AE35: 200-240V | AF35: Yes | AG35: December 2022 | AH35: No | AI35: =_xlfn.TEXTBEFORE(C35,"_") & " (" & _xlfn.TEXTAFTER(C35,"_") & ")" -> S19j Pro (88T) | AJ35: =_xlfn.TEXTBEFORE(C35,"_") & " (Vnish)" -> S19j Pro (Vnish) | AK35: 0 | AL35: 1
A36: D4F | B36: 84 | C36: S19j Pro_84T | D36: =MID(A36,1,2) -> D4 | E36: S19j Pro | F36: D4U | G36: A/B | H36: 2021/2022 | I36: 29.5 | J36: =B36*I36 -> 2478 | K36: Air | L36: BHB42601 | N36: BM1362 | O36: 126 | P36: 3 | Q36: =O36*P36 -> 378 | R36: APW121215ABC | S36: 0x71, 0x72, 0x73 | T36: Xilinx, BB, AML | U36: 0 | V36: FR4 | W36: 4 | X36: Yes | Y36: Solid Plate | Z36: 120mm | AA36: 6000 | AB36: S19 Normal-60mm | AC36: Normal Size | AD36: 2x C13 | AE36: 200-240V | AF36: Yes | AG36: December 2022 | AH36: No | AI36: =_xlfn.TEXTBEFORE(C36,"_") & " (" & _xlfn.TEXTAFTER(C36,"_") & ")" -> S19j Pro (84T) | AJ36: =_xlfn.TEXTBEFORE(C36,"_") & " (Vnish)" -> S19j Pro (Vnish) | AK36: 0 | AL36: 0
A37: D5A | B37: 94 | C37: S19j_94T | D37: =MID(A37,1,2) -> D5 | E37: S19j | F37: D5U | G37: A | H37: 2021 | I37: 34.5 | J37: =B37*I37 -> 3243 | K37: Air | L37: Unknown | N37: BM1362 | O37: 108 | P37: 3 | Q37: =O37*P37 -> 324 | R37: APW121215ABC | S37: 0x71, 0x72, 0x73 | T37: Xilinx, BB | U37: 0 | V37: FR4 | W37: 4 | X37: Yes | Y37: Solid Plate | Z37: 120mm | AA37: 6000 | AB37: S19 Normal-60mm | AC37: Normal Size | AD37: 2x C13 | AE37: 200-240V | AF37: Unknown | AG37: Unknown | AH37: Unknown | AI37: =_xlfn.TEXTBEFORE(C37,"_") & " (" & _xlfn.TEXTAFTER(C37,"_") & ")" -> S19j (94T) | AJ37: =_xlfn.TEXTBEFORE(C37,"_") & " (Vnish)" -> S19j (Vnish) | AK37: 1 | AL37: 0
A38: D5B | B38: 90 | C38: S19j_90T | D38: =MID(A38,1,2) -> D5 | E38: S19j | F38: D5U | G38: A | H38: 2021 | I38: 34.5 | J38: =B38*I38 -> 3105 | K38: Air | L38: Unknown | N38: BM1362 | O38: 108 | P38: 3 | Q38: =O38*P38 -> 324 | R38: APW121215ABC | S38: 0x71, 0x72, 0x73 | T38: Xilinx, BB | U38: 0 | V38: FR4 | W38: 4 | X38: Yes | Y38: Solid Plate | Z38: 120mm | AA38: 6000 | AB38: S19 Normal-60mm | AC38: Normal Size | AD38: 2x C13 | AE38: 200-240V | AF38: Unknown | AG38: Unknown | AH38: Unknown | AI38: =_xlfn.TEXTBEFORE(C38,"_") & " (" & _xlfn.TEXTAFTER(C38,"_") & ")" -> S19j (90T) | AJ38: =_xlfn.TEXTBEFORE(C38,"_") & " (Vnish)" -> S19j (Vnish) | AK38: 0 | AL38: 0
A39: D5C | B39: 86 | C39: S19j_86T | D39: =MID(A39,1,2) -> D5 | E39: S19j | F39: D5U | G39: A | H39: 2021 | I39: 34.5 | J39: =B39*I39 -> 2967 | K39: Air | L39: Unknown | N39: BM1362 | O39: 108 | P39: 3 | Q39: =O39*P39 -> 324 | R39: APW121215ABC | S39: 0x71, 0x72, 0x73 | T39: Xilinx, BB | U39: 0 | V39: FR4 | W39: 4 | X39: Yes | Y39: Solid Plate | Z39: 120mm | AA39: 6000 | AB39: S19 Normal-60mm | AC39: Normal Size | AD39: 2x C13 | AE39: 200-240V | AF39: Unknown | AG39: Unknown | AH39: Unknown | AI39: =_xlfn.TEXTBEFORE(C39,"_") & " (" & _xlfn.TEXTAFTER(C39,"_") & ")" -> S19j (86T) | AJ39: =_xlfn.TEXTBEFORE(C39,"_") & " (Vnish)" -> S19j (Vnish) | AK39: 0 | AL39: 0
A40: D5D | B40: 82 | C40: S19j_82T | D40: =MID(A40,1,2) -> D5 | E40: S19j | F40: D5U | G40: A | H40: 2021 | I40: 34.5 | J40: =B40*I40 -> 2829 | K40: Air | L40: Unknown | N40: BM1362 | O40: 108 | P40: 3 | Q40: =O40*P40 -> 324 | R40: APW121215ABC | S40: 0x71, 0x72, 0x73 | T40: Xilinx, BB | U40: 0 | V40: FR4 | W40: 4 | X40: Yes | Y40: Solid Plate | Z40: 120mm | AA40: 6000 | AB40: S19 Normal-60mm | AC40: Normal Size | AD40: 2x C13 | AE40: 200-240V | AF40: Unknown | AG40: Unknown | AH40: Unknown | AI40: =_xlfn.TEXTBEFORE(C40,"_") & " (" & _xlfn.TEXTAFTER(C40,"_") & ")" -> S19j (82T) | AJ40: =_xlfn.TEXTBEFORE(C40,"_") & " (Vnish)" -> S19j (Vnish) | AK40: 0 | AL40: 0
...

Sheet Mass Import Sheet
A1: Full Serial Import | B1: Special Digits | C1: Model Serial | D1: Year Serial | E1: Result | F1: Backup Result | G1: Foreman Result | H1: Hashrate | I1: Hashboard | J1: Year Of Manufacture | K1: Avalon Special Character Check | L1: Bitmain Side Serial Check
B2: =MID(A2,5,3) | C2: =MID(B2,1,2) | D2: =MID(A2,9,1) | E2: =VLOOKUP(B2,'Full Chart'!A:E,3,FALSE) -> #N/A | F2: =VLOOKUP(C2,'Full Chart'!D:E,2,FALSE) -> #N/A | G2: ="Antminer "&F2&" ("&H2&"T)" -> #N/A | H2: =VLOOKUP(B2,'Full Chart'!A:E,2,FALSE) -> #N/A | I2: =VLOOKUP(B2,'Full Chart'!A:L,12,FALSE) -> #N/A | J2: =VLOOKUP(D2,'Full Chart'!G:H,2,FALSE) -> #N/A | K2: =MID(A2,17,4) | L2: =MID(A2,7,1) | M2: Notes
B3: =MID(A3,5,3) | C3: =MID(B3,1,2) | D3: =MID(A3,9,1) | E3: =VLOOKUP(B3,'Full Chart'!A:E,3,FALSE) -> #N/A | F3: =VLOOKUP(C3,'Full Chart'!D:E,2,FALSE) -> #N/A | G3: ="Antminer "&F3&" ("&H3&"T)" -> #N/A | H3: =VLOOKUP(B3,'Full Chart'!A:E,2,FALSE) -> #N/A | I3: =VLOOKUP(B3,'Full Chart'!A:L,12,FALSE) -> #N/A | J3: =VLOOKUP(D3,'Full Chart'!G:H,2,FALSE) -> #N/A | K3: =MID(A3,17,4) | L3: =MID(A3,7,1) | M3: *Please don't use the shared sheet for your individual use of this decoder
B4: =MID(A4,5,3) | C4: =MID(B4,1,2) | D4: =MID(A4,9,1) | E4: =VLOOKUP(B4,'Full Chart'!A:E,3,FALSE) -> #N/A | F4: =VLOOKUP(C4,'Full Chart'!D:E,2,FALSE) -> #N/A | G4: ="Antminer "&F4&" ("&H4&"T)" -> #N/A | H4: =VLOOKUP(B4,'Full Chart'!A:E,2,FALSE) -> #N/A | I4: =VLOOKUP(B4,'Full Chart'!A:L,12,FALSE) -> #N/A | J4: =VLOOKUP(D4,'Full Chart'!G:H,2,FALSE) -> #N/A | K4: =MID(A4,17,4) | L4: =MID(A4,7,1) | M4: *Copy the sheet onto your computer before using it
B5: =MID(A5,5,3) | C5: =MID(B5,1,2) | D5: =MID(A5,9,1) | E5: =VLOOKUP(B5,'Full Chart'!A:E,3,FALSE) -> #N/A | F5: =VLOOKUP(C5,'Full Chart'!D:E,2,FALSE) -> #N/A | G5: ="Antminer "&F5&" ("&H5&"T)" -> #N/A | H5: =VLOOKUP(B5,'Full Chart'!A:E,2,FALSE) -> #N/A | I5: =VLOOKUP(B5,'Full Chart'!A:L,12,FALSE) -> #N/A | J5: =VLOOKUP(D5,'Full Chart'!G:H,2,FALSE) -> #N/A | K5: =MID(A5,17,4) | L5: =MID(A5,7,1) | M5: *Drag the formula columns down as far as you need them

Sheet Methodology
B2: Bitmain Serial Decoder Explained | L2: PSU Decoder | T2: Revenue per kwh
B3: Stat | C3: Factory | D3: Sub-model | E3: Hashrate | F3: The letter B | G3: Year of Manufacture | H3: J or A | I3: Serialized Section | K3: Notes | L3: Stat | M3: Factory | N3: Sub-model | O3: The letter B | P3: Year of Manufacture | Q3: Serialized Section | T3: 1000 | U3: /efficiency | V3: TH/kW | W3: Hashprice ($/th/day) | X3: /24 | Y3: rev/kwh
B4: Position in serial | C4: Character (1-4) | D4: Character (5-6) | E4: Character (7) | F4: Character (8) | G4: Character (9) | H4: Character (10) | I4: Character (11-17) | K4: *Control Board and PSU can be assumed | L4: Position in serial | M4: Character (1-4) | N4: Character (5-7) | O4: Character (8) | P4: Character (9) | Q4: Character (10-17) | T4: 1000 | U4: 5 | V4: =T4/U4 -> 200 | W4: 0.056 | X4: 24 | Y4: =V4*W4/X4 -> 0.46666667
B5: (Known) Possible Options | C5: ANZE | D5: 67 | E5: A | F5: B | G5: I | H5: J | I5: AAA0000 | K5: *Method does not work for MicroBT, Canaan, Auradine or any brand of miner other than bitmain | L5: (Known) Possible Options | M5: DGAH | N5: 30y | O5: B | P5: I | Q5: AAAA0000 | T5: 1000 | U5: 10 | V5: =T5/U5 -> 100 | W5: 0.056 | X5: 24 | Y5: =V5*W5/X5 -> 0.23333333
C6: ASPW | D6: 68 | E6: B | G6: J | H6: A | K6: *Character 7 "hashrate" must take sub-model into account | M6: DGQG | N6: 313 | P6: J | T6: 1000 | U6: 15 | V6: =T6/U6 -> 66.666667 | W6: 0.056 | X6: 24 | Y6: =V6*W6/X6 -> 0.15555556
C7: AZEC | D7: A0 | E7: C | G7: A | K7: *Character 10 is always either A or J. J is first half of the year and A is second half of the year | M7: DGYH | N7: 318 | P7: A | T7: 1000 | U7: 20 | V7: =T7/U7 -> 50 | W7: 0.056 | X7: 24 | Y7: =V7*W7/X7 -> 0.11666667
C8: BCME | D8: AD | E8: D | G8: B | K8: *Method does not work for altcoin antminers | M8: KLKT | N8: 316 | P8: B | T8: 1000 | U8: 25 | V8: =T8/U8 -> 40 | W8: 0.056 | X8: 24 | Y8: =V8*W8/X8 -> 0.093333333
C9: CMSI | D9: AE | E9: E | G9: C | K9: *Yellow on the full chart page means the line is still pending more information | M9: OLTT | N9: 324 | P9: C | T9: 1000 | U9: 30 | V9: =T9/U9 -> 33.333333 | W9: 0.056 | X9: 24 | Y9: =V9*W9/X9 -> 0.077777778
C10: E015 | D10: AT | E10: F | G10: D | N10: 323 | P10: D | T10: 1000 | U10: 35 | V10: =T10/U10 -> 28.571429 | W10: 0.056 | X10: 24 | Y10: =V10*W10/X10 -> 0.066666667
C11: E019 | D11: AW | G11: E | N11: 324 | P11: E | T11: 1000 | U11: 40 | V11: =T11/U11 -> 25 | W11: 0.056 | X11: 24 | Y11: =V11*W11/X11 -> 0.058333333
C12: E020 | D12: B0 | G12: F | N12: 329 | T12: 1000 | U12: 45 | V12: =T12/U12 -> 22.222222 | W12: 0.056 | X12: 24 | Y12: =V12*W12/X12 -> 0.051851852
C13: FXDZ | D13: B9 | N13: 335 | P13: I=2019 | T13: 1000 | U13: 50 | V13: =T13/U13 -> 20 | W13: 0.056 | X13: 24 | Y13: =V13*W13/X13 -> 0.046666667
C14: HKYQ | D14: C2 | G14: I=2019 | N14: 347 | P14: J=2020 | T14: 1000 | U14: 55 | V14: =T14/U14 -> 18.181818 | W14: 0.056 | X14: 24 | Y14: =V14*W14/X14 -> 0.042424242
C15: HQDZ | D15: D4 | G15: J=2020 | N15: 380 | P15: A=2021 | T15: 1000 | U15: 60 | V15: =T15/U15 -> 16.666667 | W15: 0.056 | X15: 24 | Y15: =V15*W15/X15 -> 0.038888889
C16: HXXY | D16: D5 | G16: A=2021 | N16: 381 | P16: B=2022 | T16: 1000 | U16: 65 | V16: =T16/U16 -> 15.384615 | W16: 0.056 | X16: 24 | Y16: =V16*W16/X16 -> 0.035897436
C17: HYDT | D17: DA | G17: B=2022 | P17: C=2023 | T17: 1000 | U17: 70 | V17: =T17/U17 -> 14.285714 | W17: 0.056 | X17: 24 | Y17: =V17*W17/X17 -> 0.033333333
C18: KPMI | D18: DB | G18: C=2023 | P18: D=2024 | T18: 1000 | U18: 75 | V18: =T18/U18 -> 13.333333 | W18: 0.056 | X18: 24 | Y18: =V18*W18/X18 -> 0.031111111
C19: MERI | D19: DW | G19: D=2024 | P19: E=2025 | T19: 1000 | U19: 80 | V19: =T19/U19 -> 12.5 | W19: 0.056 | X19: 24 | Y19: =V19*W19/X19 -> 0.029166667
C20: NGSB | D20: DX | G20: E=2025 | T20: 1000 | U20: 85 | V20: =T20/U20 -> 11.764706 | W20: 0.056 | X20: 24 | Y20: =V20*W20/X20 -> 0.02745098
C21: PIEM | D21: E3 | G21: F=2026 | T21: 1000 | U21: 90 | V21: =T21/U21 -> 11.111111 | W21: 0.056 | X21: 24 | Y21: =V21*W21/X21 -> 0.025925926
C22: SMTT | D22: E5 | T22: 1000 | U22: 95 | V22: =T22/U22 -> 10.526316 | W22: 0.056 | X22: 24 | Y22: =V22*W22/X22 -> 0.024561404
C23: THQG | D23: EA | T23: 1000 | U23: 100 | V23: =T23/U23 -> 10 | W23: 0.056 | X23: 24 | Y23: =V23*W23/X23 -> 0.023333333
C24: YDFT | D24: EM
C25: YNAH | D25: ES
C26: ONET | D26: F1
C27: DGAH | D27: F2
D28: F9
D29: FA
D30: FB
D31: FK
